<sdf version='1.6'>
  <world name='default'>
    <light name='sun' type='directional'>
      <cast_shadows>1</cast_shadows>
      <pose frame=''>0 0 10 0 -0 0</pose>
      <diffuse>0.8 0.8 0.8 1</diffuse>
      <specular>0.2 0.2 0.2 1</specular>
      <attenuation>
        <range>1000</range>
        <constant>0.9</constant>
        <linear>0.01</linear>
        <quadratic>0.001</quadratic>
      </attenuation>
      <direction>-0.5 0.1 -0.9</direction>
    </light>
    <model name='ground_plane'>
      <static>1</static>
      <link name='link'>
        <collision name='collision'>
          <geometry>
            <plane>
              <normal>0 0 1</normal>
              <size>100 100</size>
            </plane>
          </geometry>
          <surface>
            <contact>
              <collide_bitmask>65535</collide_bitmask>
              <ode/>
            </contact>
            <friction>
              <ode>
                <mu>100</mu>
                <mu2>50</mu2>
              </ode>
              <torsional>
                <ode/>
              </torsional>
            </friction>
            <bounce/>
          </surface>
          <max_contacts>10</max_contacts>
        </collision>
        <visual name='visual'>
          <cast_shadows>0</cast_shadows>
          <geometry>
            <plane>
              <normal>0 0 1</normal>
              <size>100 100</size>
            </plane>
          </geometry>
          <material>
            <script>
              <uri>file://media/materials/scripts/gazebo.material</uri>
              <name>Gazebo/Grey</name>
            </script>
          </material>
        </visual>
        <self_collide>0</self_collide>
        <enable_wind>0</enable_wind>
        <kinematic>0</kinematic>
      </link>
    </model>
    <gravity>0 0 -9.8</gravity>
    <magnetic_field>6e-06 2.3e-05 -4.2e-05</magnetic_field>
    <atmosphere type='adiabatic'/>
    <physics name='default_physics' default='0' type='ode'>
      <max_step_size>0.001</max_step_size>
      <real_time_factor>1</real_time_factor>
      <real_time_update_rate>1000</real_time_update_rate>
    </physics>
    <scene>
      <ambient>0.4 0.4 0.4 1</ambient>
      <background>0.7 0.7 0.7 1</background>
      <shadows>1</shadows>
    </scene>
    <audio>
      <device>default</device>
    </audio>
    <wind/>
    <spherical_coordinates>
      <surface_model>EARTH_WGS84</surface_model>
      <latitude_deg>0</latitude_deg>
      <longitude_deg>0</longitude_deg>
      <elevation>0</elevation>
      <heading_deg>0</heading_deg>
    </spherical_coordinates>
    <model name='digitizer_platform'>
      <link name='base_link'>
        <pose frame=''>0 0 0 0 -0 0</pose>
        <inertial>
          <pose frame=''>6e-06 -0.221159 0.280082 0 -0 0</pose>
          <mass>151.124</mass>
          <inertia>
            <ixx>107.321</ixx>
            <ixy>0.000457316</ixy>
            <ixz>-0.00091974</ixz>
            <iyy>119.004</iyy>
            <iyz>17.8412</iyz>
            <izz>45.9816</izz>
          </inertia>
        </inertial>
        <collision name='base_link_collision'>
          <pose frame=''>0 0 0 0 -0 0</pose>
          <geometry>
            <mesh>
              <scale>1 1 1</scale>
              <uri>model://digitizer_platform/meshes/base_link.STL</uri>
            </mesh>
          </geometry>
          <max_contacts>10</max_contacts>
          <surface>
            <contact>
              <ode/>
            </contact>
            <bounce/>
            <friction>
              <torsional>
                <ode/>
              </torsional>
              <ode/>
            </friction>
          </surface>
        </collision>
        <collision name='base_link_fixed_joint_lump__metals_collision_2'>
          <pose frame=''>-0.9234 0 0 1.5708 -0 0</pose>
          <geometry>
            <mesh>
              <scale>1 1 1</scale>
              <uri>model://digitizer_platform/meshes/metals.STL</uri>
            </mesh>
          </geometry>
          <max_contacts>10</max_contacts>
          <surface>
            <contact>
              <ode/>
            </contact>
            <bounce/>
            <friction>
              <torsional>
                <ode/>
              </torsional>
              <ode/>
            </friction>
          </surface>
        </collision>
        <collision name='base_link_fixed_joint_lump__nuts_collision_3'>
          <pose frame=''>0 -0.74522 2.0178 1.5708 -0 1.5708</pose>
          <geometry>
            <mesh>
              <scale>1 1 1</scale>
              <uri>model://digitizer_platform/meshes/nuts.STL</uri>
            </mesh>
          </geometry>
          <max_contacts>10</max_contacts>
          <surface>
            <contact>
              <ode/>
            </contact>
            <bounce/>
            <friction>
              <torsional>
                <ode/>
              </torsional>
              <ode/>
            </friction>
          </surface>
        </collision>
        <collision name='base_link_fixed_joint_lump__wood_collision_4'>
          <pose frame=''>-1.0574 -0.74522 1.0894 1.5708 -0 0</pose>
          <geometry>
            <mesh>
              <scale>1 1 1</scale>
              <uri>model://digitizer_platform/meshes/wood.STL</uri>
            </mesh>
          </geometry>
          <max_contacts>10</max_contacts>
          <surface>
            <contact>
              <ode/>
            </contact>
            <bounce/>
            <friction>
              <torsional>
                <ode/>
              </torsional>
              <ode/>
            </friction>
          </surface>
        </collision>
        <visual name='base_link_visual'>
          <pose frame=''>0 0 0 0 -0 0</pose>
          <geometry>
            <mesh>
              <scale>1 1 1</scale>
              <uri>model://digitizer_platform/meshes/base_link.STL</uri>
            </mesh>
          </geometry>
          <material>
            <ambient>0 0 0 1</ambient>
            <diffuse>0 0 0 1</diffuse>
            <specular>0.1 0.1 0.1 1</specular>
            <emissive>0 0 0 0</emissive>
          </material>
        </visual>
        <visual name='visual_track'>
          <cast_shadows>0</cast_shadows>
          <pose frame=''>0 0 0.02 0 -0 1.57</pose>
          <geometry>
            <plane>
              <normal>0 0 1</normal>
              <size>2.45 1.53</size>
            </plane>
          </geometry>
          <material>
            <script>
              <uri>model://digitizer_platform/materials/scripts/</uri>
              <uri>model://digitizer_platform/materials/textures</uri>
              <name>platform/Image</name>
            </script>
          </material>
        </visual>
        <visual name='base_link_fixed_joint_lump__bolts_visual_1'>
          <cast_shadows>0</cast_shadows>
          <pose frame=''>-1.1364 -0.74522 0.20829 -3.14159 -0 0</pose>
          <geometry>
            <mesh>
              <scale>1 1 1</scale>
              <uri>model://digitizer_platform/meshes/bolts.STL</uri>
            </mesh>
          </geometry>
          <material>
            <ambient>0.97 0.65 0.008 1</ambient>
            <diffuse>0.97 0.65 0.008 1</diffuse>
            <specular>0.1 0.1 0.1 1</specular>
            <emissive>0 0 0 0</emissive>
          </material>
        </visual>
        <visual name='base_link_fixed_joint_lump__metals_visual_2'>
          <cast_shadows>0</cast_shadows>
          <pose frame=''>-0.9234 0 0 1.5708 -0 0</pose>
          <geometry>
            <mesh>
              <scale>1 1 1</scale>
              <uri>model://digitizer_platform/meshes/metals.STL</uri>
            </mesh>
          </geometry>
          <material>
            <ambient>0.847 0.847 0.847 1</ambient>
            <diffuse>0.847 0.847 0.847 1</diffuse>
            <specular>0.1 0.1 0.1 1</specular>
            <emissive>0 0 0 0</emissive>
          </material>
        </visual>
        <visual name='base_link_fixed_joint_lump__wood_visual_4'>
          <cast_shadows>0</cast_shadows>
          <pose frame=''>-1.0574 -0.74522 1.0894 1.5708 -0 0</pose>
          <geometry>
            <mesh>
              <scale>1 1 1</scale>
              <uri>model://digitizer_platform/meshes/wood.STL</uri>
            </mesh>
          </geometry>
          <material>
            <ambient>0.4 0.2 0 1</ambient>
            <diffuse>0.4 0.2 0 1</diffuse>
            <specular>0.1 0.1 0.1 1</specular>
            <emissive>0 0 0 0</emissive>
          </material>
        </visual>
        <self_collide>0</self_collide>
        <enable_wind>0</enable_wind>
        <kinematic>0</kinematic>
      </link>
      <link name='cam'>
        <pose frame=''>0.00162 0 1.7002 0 1.57 1.57</pose>
        <inertial>
          <pose frame=''>-0 0.016534 -0 0 -0 0</pose>
          <mass>1.598e-05</mass>
          <inertia>
            <ixx>3.2592e-09</ixx>
            <ixy>3.6091e-24</ixy>
            <ixz>-3.8632e-24</ixz>
            <iyy>1.5702e-09</iyy>
            <iyz>4.5897e-24</iyz>
            <izz>3.2592e-09</izz>
          </inertia>
        </inertial>
        <collision name='cam_collision'>
          <pose frame=''>0 0 0 0 -0 1.57</pose>
          <geometry>
            <mesh>
              <scale>1 1 1</scale>
              <uri>model://digitizer_platform/meshes/camera.STL</uri>
            </mesh>
          </geometry>
          <max_contacts>10</max_contacts>
          <surface>
            <contact>
              <ode/>
            </contact>
            <bounce/>
            <friction>
              <torsional>
                <ode/>
              </torsional>
              <ode/>
            </friction>
          </surface>
        </collision>
        <visual name='cam_visual'>
          <cast_shadows>0</cast_shadows>
          <pose frame=''>0 0 0 0 -0 1.57</pose>
          <geometry>
            <mesh>
              <scale>1 1 1</scale>
              <uri>model://digitizer_platform/meshes/camera.STL</uri>
            </mesh>
          </geometry>
          <material>
            <ambient>0.2 0.2 0.2 1</ambient>
            <diffuse>0.2 0.2 0.2 1</diffuse>
            <specular>0.1 0.1 0.1 1</specular>
            <emissive>0 0 0 0</emissive>
          </material>
        </visual>
        <sensor name='cam' type='camera'>
          <update_rate>30</update_rate>
          <camera name='head'>
            <horizontal_fov>1.39626</horizontal_fov>
            <image>
              <width>800</width>
              <height>800</height>
              <format>R8G8B8</format>
            </image>
            <clip>
              <near>0.02</near>
              <far>300</far>
            </clip>
            <noise>
              <type>gaussian</type>
              <mean>0</mean>
              <stddev>0.007</stddev>
            </noise>
          </camera>
          <plugin name='camera_controller' filename='libgazebo_ros_camera.so'>
            <alwaysOn>1</alwaysOn>
            <updateRate>0.0</updateRate>
            <cameraName>cam</cameraName>
            <robotNamespace>/</robotNamespace>
            <imageTopicName>image_raw</imageTopicName>
            <cameraInfoTopicName>camera_info</cameraInfoTopicName>
            <frameName>base_link</frameName>
            <hackBaseline>0.07</hackBaseline>
            <distortionK1>0.0</distortionK1>
            <distortionK2>0.0</distortionK2>
            <distortionK3>0.0</distortionK3>
            <distortionT1>0.0</distortionT1>
            <distortionT2>0.0</distortionT2>
          </plugin>
        </sensor>
        <self_collide>0</self_collide>
        <enable_wind>0</enable_wind>
        <kinematic>0</kinematic>
      </link>
      <joint name='cam' type='revolute'>
        <child>cam</child>
        <parent>base_link</parent>
        <axis>
          <xyz>0 0 0</xyz>
          <limit>
            <lower>0</lower>
            <upper>0</upper>
            <effort>0</effort>
            <velocity>0</velocity>
          </limit>
          <dynamics>
            <spring_reference>0</spring_reference>
            <spring_stiffness>0</spring_stiffness>
          </dynamics>
          <use_parent_model_frame>1</use_parent_model_frame>
        </axis>
      </joint>
      <pose frame=''>0 0 0 0 -0 0</pose>
    </model>
    <model name='digitizer_bot'>
      <link name='base_link'>
        <pose frame=''>0 0 0 0 -0 0</pose>
        <inertial>
          <pose frame=''>-0.004391 0 0.038562 0 -0 0</pose>
          <mass>0.165633</mass>
          <inertia>
            <ixx>8.25166e-05</ixx>
            <ixy>6.65224e-11</ixy>
            <ixz>-3.06353e-07</ixz>
            <iyy>0.000148603</iyy>
            <iyz>1.3668e-10</iyz>
            <izz>0.000190467</izz>
          </inertia>
        </inertial>
        <collision name='base_link_collision'>
          <pose frame=''>0 0 0 0 -0 0</pose>
          <geometry>
            <mesh>
              <scale>1 1 1</scale>
              <uri>model://digitizer_bot/meshes/base_link.STL</uri>
            </mesh>
          </geometry>
          <max_contacts>10</max_contacts>
          <surface>
            <contact>
              <ode/>
            </contact>
            <bounce/>
            <friction>
              <torsional>
                <ode/>
              </torsional>
              <ode/>
            </friction>
          </surface>
        </collision>
        <collision name='base_link_fixed_joint_lump__motors_collision_1'>
          <pose frame=''>0.035 0 0.036 1.5708 -0 3.14159</pose>
          <geometry>
            <mesh>
              <scale>1 1 1</scale>
              <uri>model://digitizer_bot/meshes/motors.STL</uri>
            </mesh>
          </geometry>
          <max_contacts>10</max_contacts>
          <surface>
            <contact>
              <ode/>
            </contact>
            <bounce/>
            <friction>
              <torsional>
                <ode/>
              </torsional>
              <ode/>
            </friction>
          </surface>
        </collision>
        <visual name='base_link_visual'>
          <pose frame=''>0 0 0 0 -0 0</pose>
          <geometry>
            <mesh>
              <scale>1 1 1</scale>
              <uri>model://digitizer_bot/meshes/base_link.STL</uri>
            </mesh>
          </geometry>
          <material>
            <ambient>0.7 0.7 0.7 1</ambient>
            <diffuse>0.7 0.7 0.7 1</diffuse>
            <specular>0 0 0 0</specular>
            <emissive>0 0 0 1</emissive>
          </material>
        </visual>
        <visual name='visual_april'>
          <cast_shadows>0</cast_shadows>
          <pose frame=''>0 0 0.06 0 -0 0</pose>
          <geometry>
            <plane>
              <normal>0 0 1</normal>
              <size>0.1 0.1</size>
            </plane>
          </geometry>
          <material>
            <script>
              <uri>model://digitizer_bot/materials/scripts</uri>
              <uri>model://digitizer_bot/materials/textures</uri>
              <name>digitizer_bot/Image</name>
            </script>
          </material>
        </visual>
        <visual name='base_link_fixed_joint_lump__motors_visual_1'>
          <pose frame=''>0.035 0 0.036 1.5708 -0 3.14159</pose>
          <geometry>
            <mesh>
              <scale>1 1 1</scale>
              <uri>model://digitizer_bot/meshes/motors.STL</uri>
            </mesh>
          </geometry>
          <material>
            <ambient>0.4 0.4 0.4 1</ambient>
            <diffuse>0.4 0.4 0.4 1</diffuse>
            <specular>0 0 0 0</specular>
            <emissive>0 0 0 1</emissive>
          </material>
        </visual>
        <self_collide>0</self_collide>
        <enable_wind>0</enable_wind>
        <kinematic>0</kinematic>
      </link>
      <link name='left_front_wheel'>
        <pose frame=''>0.035 0.0645 0.036 0 -0 0</pose>
        <inertial>
          <pose frame=''>-0 0.01 0 0 -0 0</pose>
          <mass>0.035123</mass>
          <inertia>
            <ixx>1.4693e-05</ixx>
            <ixy>2.2926e-21</ixy>
            <ixz>-3.9204e-22</ixz>
            <iyy>2.7858e-05</iyy>
            <iyz>-7.9353e-25</iyz>
            <izz>1.4693e-05</izz>
          </inertia>
        </inertial>
        <collision name='left_front_wheel_collision'>
          <pose frame=''>0 0 0 0 -0 0</pose>
          <geometry>
            <mesh>
              <scale>1 1 1</scale>
              <uri>model://digitizer_bot/meshes/left_front_wheel.STL</uri>
            </mesh>
          </geometry>
          <max_contacts>10</max_contacts>
          <surface>
            <contact>
              <ode/>
            </contact>
            <bounce/>
            <friction>
              <torsional>
                <ode/>
              </torsional>
              <ode/>
            </friction>
          </surface>
        </collision>
        <visual name='left_front_wheel_visual'>
          <pose frame=''>0 0 0 0 -0 0</pose>
          <geometry>
            <mesh>
              <scale>1 1 1</scale>
              <uri>model://digitizer_bot/meshes/left_front_wheel.STL</uri>
            </mesh>
          </geometry>
          <material>
            <ambient>0.2 0.2 0.2 1</ambient>
            <diffuse>0.2 0.2 0.2 1</diffuse>
            <specular>0 0 0 0</specular>
            <emissive>0 0 0 1</emissive>
          </material>
        </visual>
        <self_collide>0</self_collide>
        <enable_wind>0</enable_wind>
        <kinematic>0</kinematic>
      </link>
      <joint name='left_front_wheel' type='revolute'>
        <child>left_front_wheel</child>
        <parent>base_link</parent>
        <axis>
          <xyz>0 1 0</xyz>
          <limit>
            <lower>-1e+16</lower>
            <upper>1e+16</upper>
          </limit>
          <dynamics>
            <spring_reference>0</spring_reference>
            <spring_stiffness>0</spring_stiffness>
          </dynamics>
          <use_parent_model_frame>1</use_parent_model_frame>
        </axis>
      </joint>
      <link name='left_rear_wheel'>
        <pose frame=''>-0.05 0.0645 0.036 0 -0 0</pose>
        <inertial>
          <pose frame=''>0 0.01 0 0 -0 0</pose>
          <mass>0.035123</mass>
          <inertia>
            <ixx>1.4693e-05</ixx>
            <ixy>1.1418e-21</ixy>
            <ixz>-3.9204e-22</ixz>
            <iyy>2.7858e-05</iyy>
            <iyz>-1.4418e-24</iyz>
            <izz>1.4693e-05</izz>
          </inertia>
        </inertial>
        <collision name='left_rear_wheel_collision'>
          <pose frame=''>0 0 0 0 -0 0</pose>
          <geometry>
            <mesh>
              <scale>1 1 1</scale>
              <uri>model://digitizer_bot/meshes/left_rear_wheel.STL</uri>
            </mesh>
          </geometry>
          <max_contacts>10</max_contacts>
          <surface>
            <contact>
              <ode/>
            </contact>
            <bounce/>
            <friction>
              <torsional>
                <ode/>
              </torsional>
              <ode/>
            </friction>
          </surface>
        </collision>
        <visual name='left_rear_wheel_visual'>
          <pose frame=''>0 0 0 0 -0 0</pose>
          <geometry>
            <mesh>
              <scale>1 1 1</scale>
              <uri>model://digitizer_bot/meshes/left_rear_wheel.STL</uri>
            </mesh>
          </geometry>
          <material>
            <ambient>0.2 0.2 0.2 1</ambient>
            <diffuse>0.2 0.2 0.2 1</diffuse>
            <specular>0 0 0 0</specular>
            <emissive>0 0 0 1</emissive>
          </material>
        </visual>
        <self_collide>0</self_collide>
        <enable_wind>0</enable_wind>
        <kinematic>0</kinematic>
      </link>
      <joint name='left_rear_wheel' type='revolute'>
        <child>left_rear_wheel</child>
        <parent>base_link</parent>
        <axis>
          <xyz>0 1 0</xyz>
          <limit>
            <lower>-1e+16</lower>
            <upper>1e+16</upper>
          </limit>
          <dynamics>
            <spring_reference>0</spring_reference>
            <spring_stiffness>0</spring_stiffness>
          </dynamics>
          <use_parent_model_frame>1</use_parent_model_frame>
        </axis>
      </joint>
      <link name='right_front_wheel'>
        <pose frame=''>0.035 -0.0645 0.036 0 -0 0</pose>
        <inertial>
          <pose frame=''>-0 -0.01 0 0 -0 0</pose>
          <mass>0.035123</mass>
          <inertia>
            <ixx>1.4693e-05</ixx>
            <ixy>1.9903e-21</ixy>
            <ixz>-3.9204e-22</ixz>
            <iyy>2.7858e-05</iyy>
            <iyz>-2.4827e-25</iyz>
            <izz>1.4693e-05</izz>
          </inertia>
        </inertial>
        <collision name='right_front_wheel_collision'>
          <pose frame=''>0 0 0 0 -0 0</pose>
          <geometry>
            <mesh>
              <scale>1 1 1</scale>
              <uri>model://digitizer_bot/meshes/right_front_wheel.STL</uri>
            </mesh>
          </geometry>
          <max_contacts>10</max_contacts>
          <surface>
            <contact>
              <ode/>
            </contact>
            <bounce/>
            <friction>
              <torsional>
                <ode/>
              </torsional>
              <ode/>
            </friction>
          </surface>
        </collision>
        <visual name='right_front_wheel_visual'>
          <pose frame=''>0 0 0 0 -0 0</pose>
          <geometry>
            <mesh>
              <scale>1 1 1</scale>
              <uri>model://digitizer_bot/meshes/right_front_wheel.STL</uri>
            </mesh>
          </geometry>
          <material>
            <ambient>0.2 0.2 0.2 1</ambient>
            <diffuse>0.2 0.2 0.2 1</diffuse>
            <specular>0 0 0 0</specular>
            <emissive>0 0 0 1</emissive>
          </material>
        </visual>
        <self_collide>0</self_collide>
        <enable_wind>0</enable_wind>
        <kinematic>0</kinematic>
      </link>
      <joint name='right_front_wheel' type='revolute'>
        <child>right_front_wheel</child>
        <parent>base_link</parent>
        <axis>
          <xyz>0 1 0</xyz>
          <limit>
            <lower>-1e+16</lower>
            <upper>1e+16</upper>
          </limit>
          <dynamics>
            <spring_reference>0</spring_reference>
            <spring_stiffness>0</spring_stiffness>
          </dynamics>
          <use_parent_model_frame>1</use_parent_model_frame>
        </axis>
      </joint>
      <link name='right_rear_wheel'>
        <pose frame=''>-0.05 -0.0645 0.036 0 -0 0</pose>
        <inertial>
          <pose frame=''>0 -0.01 0 0 -0 0</pose>
          <mass>0.035123</mass>
          <inertia>
            <ixx>1.4693e-05</ixx>
            <ixy>1.1418e-21</ixy>
            <ixz>-3.9204e-22</ixz>
            <iyy>2.7858e-05</iyy>
            <iyz>-1.4418e-24</iyz>
            <izz>1.4693e-05</izz>
          </inertia>
        </inertial>
        <collision name='right_rear_wheel_collision'>
          <pose frame=''>0 0 0 0 -0 0</pose>
          <geometry>
            <mesh>
              <scale>1 1 1</scale>
              <uri>model://digitizer_bot/meshes/right_rear_wheel.STL</uri>
            </mesh>
          </geometry>
          <max_contacts>10</max_contacts>
          <surface>
            <contact>
              <ode/>
            </contact>
            <bounce/>
            <friction>
              <torsional>
                <ode/>
              </torsional>
              <ode/>
            </friction>
          </surface>
        </collision>
        <visual name='right_rear_wheel_visual'>
          <pose frame=''>0 0 0 0 -0 0</pose>
          <geometry>
            <mesh>
              <scale>1 1 1</scale>
              <uri>model://digitizer_bot/meshes/right_rear_wheel.STL</uri>
            </mesh>
          </geometry>
          <material>
            <ambient>0.2 0.2 0.2 1</ambient>
            <diffuse>0.2 0.2 0.2 1</diffuse>
            <specular>0 0 0 0</specular>
            <emissive>0 0 0 1</emissive>
          </material>
        </visual>
        <self_collide>0</self_collide>
        <enable_wind>0</enable_wind>
        <kinematic>0</kinematic>
      </link>
      <joint name='right_rear_wheel' type='revolute'>
        <child>right_rear_wheel</child>
        <parent>base_link</parent>
        <axis>
          <xyz>0 1 0</xyz>
          <limit>
            <lower>-1e+16</lower>
            <upper>1e+16</upper>
          </limit>
          <dynamics>
            <spring_reference>0</spring_reference>
            <spring_stiffness>0</spring_stiffness>
          </dynamics>
          <use_parent_model_frame>1</use_parent_model_frame>
        </axis>
      </joint>
      <plugin name='skid_steer_drive_controller' filename='libgazebo_ros_skid_steer_drive.so'>
        <updateRate>100.0</updateRate>
        <robotNamespace>/</robotNamespace>
        <leftFrontJoint>left_front_wheel</leftFrontJoint>
        <rightFrontJoint>right_front_wheel</rightFrontJoint>
        <leftRearJoint>left_rear_wheel</leftRearJoint>
        <rightRearJoint>right_rear_wheel</rightRearJoint>
        <wheelSeparation>0.129</wheelSeparation>
        <wheelDiameter>0.07</wheelDiameter>
        <robotBaseFrame>base_link</robotBaseFrame>
        <torque>20</torque>
        <topicName>cmd_vel</topicName>
        <broadcastTF>0</broadcastTF>
      </plugin>
      <pose frame=''>0.107971 -1.09758 0 0 -0 0</pose>
    </model>
    <state world_name='default'>
      <sim_time>47 904000000</sim_time>
      <real_time>48 437857970</real_time>
      <wall_time>1603018111 808610653</wall_time>
      <iterations>47904</iterations>
      <model name='digitizer_bot'>
        <pose frame=''>0.108889 -1.10065 0.016954 -0.000574 1.1e-05 -0.006506</pose>
        <scale>1 1 1</scale>
        <link name='base_link'>
          <pose frame=''>0.108889 -1.10065 0.016954 -0.000574 1.1e-05 -0.006506</pose>
          <velocity>0.000188 -0.000187 0.009144 -0.001278 -0.001818 0.000501</velocity>
          <acceleration>-0.034026 0.005148 18.6953 1.86274 -0.413981 -2.90325</acceleration>
          <wrench>-0.005636 0.000853 3.09656 0 -0 0</wrench>
        </link>
        <link name='left_front_wheel'>
          <pose frame=''>0.144308 -1.03636 0.052916 -0.000565 0.007419 -0.006507</pose>
          <velocity>6e-05 -8.7e-05 0.00908 0.002998 0.000621 0.001789</velocity>
          <acceleration>-0.10861 0.05696 18.7037 -1.9181 -0.313354 2.06141</acceleration>
          <wrench>-0.003815 0.002001 0.65693 0 -0 0</wrench>
        </link>
        <link name='left_rear_wheel'>
          <pose frame=''>0.05931 -1.03581 0.052917 -0.000566 0.007569 -0.006508</pose>
          <velocity>7.1e-05 -6.7e-05 0.008739 0.002349 0.001102 0.001569</velocity>
          <acceleration>-0.087867 0.126547 18.1934 -2.8659 0.172289 1.75466</acceleration>
          <wrench>-0.003086 0.004445 0.639007 0 -0 0</wrench>
        </link>
        <link name='right_front_wheel'>
          <pose frame=''>0.143469 -1.16536 0.05299 -0.000566 -0.054303 -0.006473</pose>
          <velocity>8.7e-05 -7.9e-05 0.009283 0.002909 0.002409 0.001265</velocity>
          <acceleration>-0.096355 0.068812 18.8277 -2.08968 1.47551 1.35989</acceleration>
          <wrench>-0.003384 0.002417 0.661286 0 -0 0</wrench>
        </link>
        <link name='right_rear_wheel'>
          <pose frame=''>0.05847 -1.1648 0.052992 -0.000564 -0.055813 -0.006472</pose>
          <velocity>8.9e-05 -0.000105 0.009326 0.003661 0.002467 0.001533</velocity>
          <acceleration>-0.089001 0.072008 18.8707 -1.00764 1.52822 1.75123</acceleration>
          <wrench>-0.003126 0.002529 0.662795 0 -0 0</wrench>
        </link>
      </model>
      <model name='digitizer_platform'>
        <pose frame=''>0.000846 -0.000663 1e-06 -3e-06 0 -0.000549</pose>
        <scale>1 1 1</scale>
        <link name='base_link'>
          <pose frame=''>0.000846 -0.000663 1e-06 -3e-06 0 -0.000549</pose>
          <velocity>-0 -0 -0.001725 -0.00142 -0 0</velocity>
          <acceleration>0.000318 1.53863 -5.54406 0.789762 0.00151 0.001165</acceleration>
          <wrench>0.048091 232.524 -837.841 0 -0 0</wrench>
        </link>
        <link name='cam'>
          <pose frame=''>0.002466 -0.000658 1.7002 0 1.57 1.56945</pose>
          <velocity>-0 0.002413 -0.001725 -0.00142 -0 0</velocity>
          <acceleration>0.001798 9.33986 -6.75914 1.16154 0.00878 -0.00011</acceleration>
          <wrench>0 0.000149 -0.000108 0 -0 0</wrench>
        </link>
      </model>
      <model name='ground_plane'>
        <pose frame=''>0 0 0 0 -0 0</pose>
        <scale>1 1 1</scale>
        <link name='link'>
          <pose frame=''>0 0 0 0 -0 0</pose>
          <velocity>0 0 0 0 -0 0</velocity>
          <acceleration>0 0 0 0 -0 0</acceleration>
          <wrench>0 0 0 0 -0 0</wrench>
        </link>
      </model>
      <light name='sun'>
        <pose frame=''>0 0 10 0 -0 0</pose>
      </light>
    </state>
    <gui fullscreen='0'>
      <camera name='user_camera'>
        <pose frame=''>1.0588 -2.07777 2.11015 -0 0.627642 2.40819</pose>
        <view_controller>orbit</view_controller>
        <projection_type>perspective</projection_type>
      </camera>
    </gui>
  </world>
</sdf>
